Workbook

Sheet RESUMEN Costos
A1: CUADRO DE COSTOS
A2: PROGRAMA DE AGUA POTABLE Y SANEAMIENTO EN EL SALVADOR
A3: ES-L 1152
B5: COMPONENTES | C5: TOTAL BID | D5: %
B6: =+'Componente 1'!B6:C6 -> Componente 1 - Reducción de los niveles de agua no contabilizada | C6: =+C7+C8 -> 33800352 | D6: =+C6/C14 -> 0.33800352
B7: Muestra | C7: =+'RESUMEN Desembolso'!C6 -> 25300352
B8: Otras Inversiones fuera de la Muestra | C8: =+'RESUMEN Desembolso'!C7 -> 8500000
B9: =+'Componente 2'!B7:C7 -> Componente 2 - Mejora de la eficiencia energética | C9: =SUM(C10:C11) -> 53549414 | D9: =+C9/C14 -> 0.53549414
B10: Muestra | C10: =+'RESUMEN Desembolso'!C9 -> 17439584
B11: Otras Inversiones fuera de la Muestra | C11: =+'RESUMEN Desembolso'!C10 -> 36109830
B12: =+'Componente 3'!B7:C7 -> Componente 3 - Mejora de la Gestión | C12: =+'Componente 3'!E7 -> 9150234 | D12: =+C12/C14 -> 0.09150234
B13: Administración, Evaluación y Auditoria | C13: =+'RESUMEN Desembolso'!C12 -> 3500000 | D13: =+C13/C14 -> 0.035
B14: TOTAL | C14: =+C6+C9+C12+C13 -> 1e+08 | D14: =SUM(D6:D13) -> 1

Sheet RESUMEN Desembolso
A1: CUADRO DE DESEMBOLSOS
A2: PROGRAMA DE AGUA POTABLE Y SANEAMIENTO EN EL SALVADOR
A3: ES-L 1152
B4: COMPONENTES | C4: TOTAL BID | D4: Año 1 | E4: Año 2 | F4: Año3 | G4: Año 4 | H4: Año 5 | I4: Total
B5: =+'Componente 1'!B6:C6 -> Componente 1 - Reducción de los niveles de agua no contabilizada | C5: =+C6+C7 -> 33800352 | D5: =+D6+D7 -> 3243778 | E5: =+E6+E7 -> 4355603.4 | F5: =+F6+F7 -> 11681416 | G5: =+G6+G7 -> 11119555 | H5: =+H6+H7 -> 3400000 | I5: =+H5+G5+F5+E5+D5 -> 33800352
B6: Muestra | C6: =+'Componente 1'!F7 -> 25300352 | D6: =+'Componente 1'!G7 -> 3243778 | E6: =+'Componente 1'!H7 -> 4355603.4 | F6: =+'Componente 1'!I7 -> 9981415.6 | G6: =+'Componente 1'!J7 -> 7719555 | H6: =+'Componente 1'!K7 -> 0 | I6: =+H6+G6+F6+E6+D6 -> 25300352
B7: Otras Inversiones fuera de la Muestra | C7: =+'Componente 1'!F17 -> 8500000 | D7: =+'Componente 1'!G17 -> 0 | E7: =+'Componente 1'!H17 -> 0 | F7: =+'Componente 1'!I17 -> 1700000 | G7: =+'Componente 1'!J17 -> 3400000 | H7: =+'Componente 1'!K17 -> 3400000 | I7: =+H7+G7+F7+E7+D7 -> 8500000
B8: =+'Componente 2'!B7:C7 -> Componente 2 - Mejora de la eficiencia energética | C8: =SUM(C9:C10) -> 53549414 | D8: =SUM(D9:D10) -> 4414070.7 | E8: =SUM(E9:E10) -> 13025513 | F8: =SUM(F9:F10) -> 5534154 | G8: =SUM(G9:G10) -> 14800693 | H8: =SUM(H9:H10) -> 15774983 | I8: =+H8+G8+F8+E8+D8 -> 53549414
B9: Muestra | C9: =+'Componente 2'!F8 -> 17439584 | D9: =+'Componente 2'!G8 -> 4414070.7 | E9: =+'Componente 2'!H8 -> 13025513 | F9: =+'Componente 2'!I8 -> 0 | G9: =+'Componente 2'!J8 -> 0 | H9: =+'Componente 2'!K8 -> 0 | I9: =+H9+G9+F9+E9+D9 -> 17439584
B10: Otras Inversiones fuera de la Muestra | C10: =+'Componente 2'!F29 -> 36109830 | D10: =+'Componente 2'!G29 -> 0 | E10: =+'Componente 2'!H29 -> 0 | F10: =+'Componente 2'!I29 -> 5534154 | G10: =+'Componente 2'!J29 -> 14800693 | H10: =+'Componente 2'!K29 -> 15774983 | I10: =+H10+G10+F10+E10+D10 -> 36109830
B11: =+'Componente 3'!B7:C7 -> Componente 3 - Mejora de la Gestión | C11: =+'Componente 3'!E7 -> 9150234 | D11: =+'Componente 3'!F7 -> 1790046.8 | E11: =+'Componente 3'!G7 -> 1297570.2 | F11: =+'Componente 3'!H7 -> 2322617 | G11: =+'Componente 3'!I7 -> 3050000 | H11: =+'Componente 3'!J7 -> 690000 | I11: =+H11+G11+F11+E11+D11 -> 9150234
B12: Administración, Evaluación y Auditoria | C12: =+Administración!D38 -> 3500000 | D12: =870000 -> 870000 | E12: =580000 -> 580000 | F12: =680000 -> 680000 | G12: 550000 | H12: 820000 | I12: =+H12+G12+F12+E12+D12 -> 3500000
B13: TOTAL | C13: =+C5+C8+C11+C12 -> 1e+08 | D13: =+D5+D8+D11+D12 -> 10317896 | E13: =+E5+E8+E11+E12 -> 19258687 | F13: =+F5+F8+F11+F12 -> 20218187 | G13: =+G5+G8+G11+G12 -> 29520248 | H13: =+H5+H8+H11+H12 -> 20684983 | I13: =+I5+I8+I11+I12 -> 1e+08
C14: 100000000 | D14: =+D13/$C$13 -> 0.10317896 | E14: =+E13/$C$13 -> 0.19258687 | F14: =+F13/$C$13 -> 0.20218187 | G14: =+G13/$C$13 -> 0.29520248 | H14: =+H13/$C$13 -> 0.20684983 | I14: =+I13/$C$13 -> 1
C16: Muestra | D16: =+C6+C9 -> 42739936

Sheet Componente 1
A1: CUADRO DE COSTOS Y DESEMBOLSO
A2: PROGRAMA DE AGUA POTABLE Y SANEAMIENTO EN EL SALVADOR
A3: ES-L 1152
G4: BID (US$)
B5: COMPONENTES | C5: Unidad | D5: Cantidad | E5: Costo Unitario (USD) | F5: Total BID (USD) | G5: AÑO 1 | H5: AÑO 2 | I5: AÑO 3 | J5: AÑO 4 | K5: AÑO 5
A6: 1 | B6: Componente 1 - Reducción de los niveles de agua no contabilizada | F6: =+F7+F17 -> 33800352 | G6: =+G7+G17 -> 3243778 | H6: =+H7+H17 -> 4355603.4 | I6: =+I7+I17 -> 11681416 | J6: =+J7+J17 -> 11119555 | K6: =+K7+K17 -> 3400000
B7: MUESTRA DEL PROGRAMA | F7: =+F8+F12+F14 -> 25300352 | G7: =+G8+G12+G14 -> 3243778 | H7: =+H8+H12+H14 -> 4355603.4 | I7: =+I8+I12+I14 -> 9981415.6 | J7: =+J8+J12+J14 -> 7719555 | K7: =+K8+K12 -> 0
A8: 1.1 | B8: Sectorización, regulación y monitoreo de la red de distribución (Sistema Zona Norte solamente) | F8: =+F9+F10+F11 -> 12926000 | G8: =+G9+G10+G11 -> 1641602 | H8: =+H9+H10+H11 -> 1880733 | I8: =+I9+I10+I11 -> 6269110 | J8: =+J9+J10+J11 -> 3134555 | K8: =+K9+K10+K11 -> 0
A9: 1.1.1 | B9: Obra | C9: Suma alzada | D9: 1 | E9: =+'Costos desglosados_C1 y C2'!F161-'Costos desglosados_C1 y C2'!J161 -> 11633400 | F9: =+E9*D9 -> 11633400 | G9: =+F9*0.1 -> 1163340 | H9: =+F9*0.15 -> 1745010 | I9: =F9*0.5 -> 5816700 | J9: =F9*0.25 -> 2908350 | K9: 0
A10: 1.1.3 | B10: Diseño Ejecutivo de Obra | C10: Suma alzada | D10: 1 | E10: =+'Costos desglosados_C1 y C2'!J161*30% -> 387780 | F10: =+E10 -> 387780 | G10: =+F10 -> 387780 | H10: 0 | I10: 0 | J10: 0 | K10: 0
A11: 1.1.4 | B11: Supervisión de Obra | C11: Suma alzada | D11: 1 | E11: =+'Costos desglosados_C1 y C2'!J161*70% -> 904820 | F11: =+E11 -> 904820 | G11: =+F11*0.1 -> 90482 | H11: =+F11*0.15 -> 135723 | I11: =F11*0.5 -> 452410 | J11: =F11*0.25 -> 226205 | K11: 0
A12: 1.2 | B12: Rehabilitación y gestión del parque de medidores | F12: =SUM(F13:F13) -> 9170000 | G12: =SUM(G13:G13) -> 0 | H12: =SUM(H13:H13) -> 1834000 | I12: =SUM(I13:I13) -> 2751000 | J12: =SUM(J13:J13) -> 4585000 | K12: =SUM(K13:K13) -> 0
A13: 1.2.1 | B13: Adquisición de 200 mil medidores | C13: Suma alzada | D13: 1 | E13: =+'Costos desglosados_C1 y C2'!G190 -> 9170000 | F13: =+E13*D13 -> 9170000 | G13: 0 | H13: =F13*0.2 -> 1834000 | I13: =+F13*0.3 -> 2751000 | J13: =+F13/2 -> 4585000 | K13: 0
A14: 2.6 | B14: Adquisición de bienes y herramientas para operación y gestión | F14: =+F15+F16 -> 3204352 | G14: =+G15+G16 -> 1602176 | H14: =+H15+H16 -> 640870.4 | I14: =+I15+I16 -> 961305.6 | J14: =SUM(J16:J16) -> 0 | K14: =SUM(K16:K16) -> 0
A15: 2.6.1 | B15: Adquisición de equipos para a gestión de ANDA | C15: Suma alzada | D15: 1 | E15: =+'Costos desglosados_C1 y C2'!F202 -> 9593500 | F15: 1000000 | G15: =F15*0.5 -> 500000 | H15: =F15*0.2 -> 200000 | I15: =F15*0.3 -> 300000
A16: 2.6.2 | B16: Adquisición de maquinarias para la operación de ANDA | C16: Suma alzada | D16: 1 | F16: 2204352 | G16: =F16*0.5 -> 1102176 | H16: =F16*0.2 -> 440870.4 | I16: =F16*0.3 -> 661305.6 | J16: 0 | K16: 0
B17: OTRAS INVERSIONES FUERA DE LA MUESTRA | F17: =+F18 -> 8500000 | G17: =+G18 -> 0 | H17: =+H18 -> 0 | I17: =+I18 -> 1700000 | J17: =+J18 -> 3400000 | K17: =+K18 -> 3400000
A18: 1.3 | B18: Proyectos de sectorización, regulación y monitoreo de la red de distribución en el AMSS que no están en la muestra implementados | C18: Suma alzada | D18: 1 | E18: 8500000 | F18: 8500000 | G18: 0 | H18: 0 | I18: =F18*0.2 -> 1700000 | J18: =F18*0.4 -> 3400000 | K18: =F18*0.4 -> 3400000

Sheet Componente 2
A1: CUADRO DE COSTOS Y DESEMBOLSO
A2: PROGRAMA DE AGUA POTABLE Y SANEAMIENTO EN EL SALVADOR
A3: ES-L 1152
G4: AÑO 1 | H4: AÑO 2 | I4: AÑO 3 | J4: AÑO 4 | K4: AÑO 5
B5: COMPONENTES | C5: Unidad | D5: Cantidad | E5: Costo Unitario (USD) | F5: Total (USD) | G5: BID (USD) | H5: BID (USD) | I5: BID (USD) | J5: BID (USD) | K5: BID (USD)
A7: 2 | B7: Componente 2 - Mejora de la eficiencia energética | F7: =+F8+F29 -> 53549414 | G7: =+G8+G29 -> 4414070.7 | H7: =+H8+H29 -> 13025513 | I7: =+I8+I29 -> 5534154 | J7: =+J8+J29 -> 14800693 | K7: =+K8+K29 -> 15774983
B8: MUESTRA DEL PROGRAMA | F8: =+F9+F13+F17+F21+F25 -> 17439584 | G8: =+G9+G13+G17+G21+G25 -> 4414070.7 | H8: =+H9+H13+H17+H21+H25 -> 13025513 | I8: =+I9+I13+I17+I21+I25 -> 0 | J8: =+J9+J13+J17+J21+J25 -> 0 | K8: =+K9+K13+K17+K21+K25 -> 0
A9: 2.1 | B9: Refuerzo de la producción del Sistema Zona Norte | F9: =SUM(F10:F12) -> 4665083.6 | G9: =SUM(G10:G12) -> 1035378.7 | H9: =SUM(H10:H12) -> 3629704.9 | I9: =SUM(I10:I12) -> 0 | J9: =SUM(J10:J12) -> 0 | K9: =SUM(K10:K12) -> 0
A10: 2.1.1 | B10: Obras | C10: Suma alzada | D10: 1 | E10: =+'Costos desglosados_C1 y C2'!G6+'Costos desglosados_C1 y C2'!H6+'Costos desglosados_C1 y C2'!I6 -> 4238575.3 | F10: =+E10*D10 -> 4238575.3 | G10: =F10*0.2 -> 847715.05 | H10: =+F10*0.8 -> 3390860.2 | I10: 0 | J10: 0 | K10: 0
A11: 2.1.2 | B11: Diseño Ejecutivo (3% de obra) | C11: Suma alzada | D11: 1 | E11: =+'Costos desglosados_C1 y C2'!J6*0.3 -> 127952.51 | F11: =+E11*D11 -> 127952.51 | G11: =+F11 -> 127952.51 | H11: 0 | I11: 0 | J11: 0 | K11: 0
A12: 2.1.3 | B12: Supervisión de Obra (7% de obra) | C12: Suma alzada | D12: 1 | E12: =+'Costos desglosados_C1 y C2'!J6*0.7 -> 298555.85 | F12: =+E12*D12 -> 298555.85 | G12: =+F12*0.2 -> 59711.171 | H12: =+F12*0.8 -> 238844.68 | I12: 0 | J12: 0 | K12: 0
A13: 2.2 | B13: Refuerzo de la Línea de Conducción entre Pozos y la Estación de Bombeo La Toma | C13: Suma alzada | F13: =SUM(F14:F16) -> 6148000 | G13: =SUM(G14:G16) -> 1377152 | H13: =SUM(H14:H16) -> 4770848 | I13: =SUM(I14:I16) -> 0 | J13: =SUM(J14:J16) -> 0 | K13: =SUM(K14:K16) -> 0
A14: 2.2.1 | B14: Obras | C14: Suma alzada | D14: 1 | E14: =+'Costos desglosados_C1 y C2'!G17+'Costos desglosados_C1 y C2'!H17+'Costos desglosados_C1 y C2'!I17 -> 5533200 | F14: =+E14*D14 -> 5533200 | G14: =F14*0.2 -> 1106640 | H14: =+F14*0.8 -> 4426560 | I14: 0 | J14: 0 | K14: 0
A15: 2.2.2 | B15: Diseño Ejecutivo (3% de obra) | C15: Suma alzada | D15: 1 | E15: =+'Costos desglosados_C1 y C2'!J17*0.3 -> 184440 | F15: =+E15*D15 -> 184440 | G15: =+F15 -> 184440 | H15: 0 | I15: 0 | J15: 0 | K15: 0
A16: 2.2.3 | B16: Supervisión de Obra (7% de obra) | C16: Suma alzada | D16: 1 | E16: =+'Costos desglosados_C1 y C2'!J17*0.7 -> 430360 | F16: =+E16*D16 -> 430360 | G16: =+F16*0.2 -> 86072 | H16: =+F16*0.8 -> 344288 | I16: 0 | J16: 0 | K16: 0
A17: 2.3 | B17: Refuerzo de la Linea de Conducción La Toma / EB Central | F17: =SUM(F18:F20) -> 3400000 | G17: =SUM(G18:G20) -> 761600 | H17: =SUM(H18:H20) -> 2638400 | I17: =SUM(I18:I20) -> 0 | J17: =SUM(J18:J20) -> 0 | K17: =SUM(K18:K20) -> 0
A18: 2.3.1 | B18: Obras | C18: Suma alzada | D18: 1 | E18: =+'Costos desglosados_C1 y C2'!G71+'Costos desglosados_C1 y C2'!H71+'Costos desglosados_C1 y C2'!I71 -> 3060000 | F18: =+E18*D18 -> 3060000 | G18: =F18*0.2 -> 612000 | H18: =+F18*0.8 -> 2448000 | I18: 0 | J18: 0 | K18: 0
A19: 2.3.2 | B19: Diseño Ejecutivo (3% de obra) | C19: Suma alzada | D19: 1 | E19: =+'Costos desglosados_C1 y C2'!J71*0.3 -> 102000 | F19: =+E19*D19 -> 102000 | G19: =+F19 -> 102000 | H19: 0 | I19: 0 | J19: 0 | K19: 0
A20: 2.3.3 | B20: Supervisión de Obra (7% de obra) | C20: Suma alzada | D20: 1 | E20: =+'Costos desglosados_C1 y C2'!J71*0.7 -> 238000 | F20: =+E20*D20 -> 238000 | G20: =+F20*0.2 -> 47600 | H20: =+F20*0.8 -> 190400 | I20: 0 | J20: 0 | K20: 0
A21: 2.4 | B21: Adecuación de la Conducción de la EB Central / EB San Ramón A | F21: =SUM(F22:F24) -> 2560000 | G21: =SUM(G22:G24) -> 573440 | H21: =SUM(H22:H24) -> 1986560 | I21: =SUM(I22:I24) -> 0 | J21: =SUM(J22:J24) -> 0 | K21: =SUM(K22:K24) -> 0
A22: 2.4.1 | B22: Obras | C22: Suma alzada | D22: 1 | E22: =+'Costos desglosados_C1 y C2'!G109+'Costos desglosados_C1 y C2'!H109+'Costos desglosados_C1 y C2'!I109 -> 2304000 | F22: =+E22*D22 -> 2304000 | G22: =F22*0.2 -> 460800 | H22: =+F22*0.8 -> 1843200 | I22: 0 | J22: 0 | K22: 0
A23: 2.4.2 | B23: Diseño Ejecutivo (3% de obra) | C23: Suma alzada | D23: 1 | E23: =+'Costos desglosados_C1 y C2'!J109*0.3 -> 76800 | F23: =+E23*D23 -> 76800 | G23: =+F23 -> 76800 | H23: 0 | I23: 0 | J23: 0 | K23: 0
A24: 2.4.3 | B24: Supervisión de Obra (7% de obra) | C24: Suma alzada | D24: 1 | E24: =+'Costos desglosados_C1 y C2'!J109*0.7 -> 179200 | F24: =+E24*D24 -> 179200 | G24: =+F24*0.2 -> 35840 | H24: =+F24*0.8 -> 143360 | I24: 0 | J24: 0 | K24: 0
A25: 2.5 | B25: Rehabilitación Subestación Nejapa | F25: =SUM(F26:F28) -> 666500 | G25: =SUM(G26:G28) -> 666500 | H25: =SUM(H26:H28) -> 0 | I25: =SUM(I26:I28) -> 0 | J25: =SUM(J26:J28) -> 0 | K25: =SUM(K26:K28) -> 0
A26: 2.5.1 | B26: Obras | C26: Suma alzada | D26: 1 | E26: =+'Costos desglosados_C1 y C2'!G137+'Costos desglosados_C1 y C2'!H137+'Costos desglosados_C1 y C2'!I137 -> 599850 | F26: =+E26*D26 -> 599850 | G26: =+F26 -> 599850 | H26: 0 | I26: 0 | J26: 0 | K26: 0
A27: 2.5.2 | B27: Diseño Ejecutivo (3% de obra) | C27: Suma alzada | D27: 1 | E27: =+'Costos desglosados_C1 y C2'!J137*0.3 -> 19995 | F27: =+E27*D27 -> 19995 | G27: =+F27 -> 19995 | H27: 0 | I27: 0 | J27: 0 | K27: 0
A28: 2.5.3 | B28: Supervisión de Obra (7% de obra) | C28: Suma alzada | D28: 1 | E28: =+'Costos desglosados_C1 y C2'!J137*0.7 -> 46655 | F28: =+E28*D28 -> 46655 | G28: =+F28 -> 46655 | H28: 0 | I28: 0 | J28: 0 | K28: 0
B29: OTRAS INVERSIONES FUERA DE LA MUESTRA | F29: =+F30 -> 36109830 | G29: =+G30 -> 0 | H29: =+H30 -> 0 | I29: =+I30 -> 5534154 | J29: =+J30 -> 14800693 | K29: =+K30+2000000 -> 15774983
A30: 2.7 | B30: Proyectos de mejora de la eficiencia energética que no están en la muestra implementados. | C30: Suma alzada | D30: 1 | E30: 36109830 | F30: =+E30 -> 36109830 | G30: 0 | H30: 0 | I30: 5534154 | J30: 14800693 | K30: 13774983

Sheet Componente 3
A1: CUADRO DE COSTOS Y DESEMBOLSO
A2: PROGRAMA DE AGUA POTABLE Y SANEAMIENTO EN EL SALVADOR
A3: ES-L 1152
B5: COMPONENTES | C5: Unidad | D5: Cantidad | E5: BID (USD) | F5: Año 1 | G5: Año2 | H5: Año 3 | I5: Año 4 | J5: Año 5
A7: 3 | B7: Componente 3 - Mejora de la Gestión | E7: =SUM(E8:E16) -> 9150234 | F7: =SUM(F8:F16) -> 1790046.8 | G7: =SUM(G8:G16) -> 1297570.2 | H7: =SUM(H8:H16) -> 2322617 | I7: =SUM(I8:I16) -> 3050000 | J7: =SUM(J8:J16) -> 690000
A8: 3.1 | B8: Plan de desarrollo organizacional de ANDA diseñado e implementado | C8: Suma alzada | D8: 1 | E8: 525234 | F8: =+E8*0.2 -> 105046.8 | G8: =+E8*0.3 -> 157570.2 | H8: =+E8*0.5 -> 262617 | I8: 0 | J8: 0
A9: 3.2 | B9: Plan de accion de Gobierno Coporativo implementado ( al menos 3 actividades) | C9: Suma alzada | D9: 1 | E9: 200000 | F9: 0 | G9: 0 | H9: 0 | I9: =+E9 -> 200000 | J9: 0
A10: 3.3 | B10: Plan de modernizacion tecnologica de ANDA diseñado e implementado | C10: Suma alzada | D10: 1 | E10: 4000000 | F10: =+E10*0.3 -> 1200000 | G10: =+E10*0.2 -> 800000 | H10: =+E10*0.2 -> 800000 | I10: =+E10*0.3 -> 1200000 | J10: 0
A11: 3.4 | B11: Actividades de Genero | C11: Suma alzada | D11: 1 | E11: 75000 | F11: =+E11 -> 75000 | G11: 0 | H11: 0 | I11: 0 | J11: 0
A12: 3.5 | B12: Plan Maestro Agua y Saneamiento para el Area Metropolitana de San Salvador desarrollado (aprobado por Junta) (en ejecución) | C12: Suma alzada | D12: 1 | E12: 1800000 | F12: 0 | G12: 0 | H12: =+E12*0.3 -> 540000 | I12: =+E12*0.5 -> 900000 | J12: =+E12*0.2 -> 360000
A13: 3.6 | B13: Programa de Planificiación financiera y estrategica implementado | C13: Suma alzada | D13: 1 | E13: 1400000 | F13: 0 | G13: 0 | H13: =+E13*0.3 -> 420000 | I13: =+E13*0.5 -> 700000 | J13: =+E13*0.2 -> 280000
A14: 3.7 | B14: Plan de comunicacion diseñado e implementado | C14: Suma alzada | D14: 1 | E14: 250000 | F14: =+E14/5 -> 50000 | G14: =+F14 -> 50000 | H14: =+G14 -> 50000 | I14: =+H14 -> 50000 | J14: =+I14 -> 50000
A15: 3.8 | B15: Normas tecnicas de ANDA actualizadas | C15: Suma alzada | D15: 1 | E15: 200000 | F15: =+E15*0.4 -> 80000 | G15: =+E15*0.4 -> 80000 | H15: =+E15*0.2 -> 40000 | I15: 0 | J15: 0
A16: 3.9 | B16: Laboratorio de calidad de agua equipado | C16: Suma alzada | D16: 1 | E16: 700000 | F16: =+E16*0.4 -> 280000 | G16: =+E16*0.3 -> 210000 | H16: =+E16*0.3 -> 210000 | I16: 0 | J16: 0

Sheet Administración
A3: ES-L1152 - PRESUPUESTO Costo de Administración - US$
B4: año 1 | D4: año 2 | F4: año 3 | H4: año 4 | J4: año 5
B5: COSTO MENSUAL | C5: COSTO ANUAL | D5: COSTO MENSUAL | E5: COSTO ANUAL | F5: COSTO MENSUAL | G5: COSTO ANUAL | H5: COSTO MENSUAL | I5: COSTO ANUAL | J5: COSTO MENSUAL | K5: COSTO ANUAL | L5: TOTAL
A6: Director del Programa | B6: =5000 -> 5000 | C6: =+B6*12 -> 60000 | D6: =+B6*(1+$P$5) -> 5000 | E6: =+D6*12 -> 60000 | F6: =+D6*(1+$P$5) -> 5000 | G6: =+F6*12 -> 60000 | H6: =+F6*(1+$P$5) -> 5000 | I6: =+H6*12 -> 60000 | J6: =+H6*(1+$P$5) -> 5000 | K6: =+J6*12 -> 60000 | L6: =+E6+G6+I6+K6+C6 -> 300000
A7: Esp. Financiero | B7: =3500 -> 3500 | C7: =+B7*12 -> 42000 | D7: =+B7*(1+$P$5) -> 3500 | E7: =+D7*12 -> 42000 | F7: =+D7*(1+$P$5) -> 3500 | G7: =+F7*12 -> 42000 | H7: =+F7*(1+$P$5) -> 3500 | I7: =+H7*12 -> 42000 | J7: =+H7*(1+$P$5) -> 3500 | K7: =+J7*12 -> 42000 | L7: =+E7+G7+I7+K7+C7 -> 210000
A8: Esp. Adquisiciones | B8: =+B7 -> 3500 | C8: =+B8*12 -> 42000 | D8: =+B8*(1+$P$5) -> 3500 | E8: =+D8*12 -> 42000 | F8: =+D8*(1+$P$5) -> 3500 | G8: =+F8*12 -> 42000 | H8: =+F8*(1+$P$5) -> 3500 | I8: =+H8*12 -> 42000 | J8: =+H8*(1+$P$5) -> 3500 | K8: =+J8*12 -> 42000 | L8: =+E8+G8+I8+K8+C8 -> 210000
A9: Esp. Fortalecimiento Institucional | B9: =+B8 -> 3500 | C9: =+B9*12 -> 42000 | D9: =+B9*(1+$P$5) -> 3500 | E9: =+D9*12 -> 42000 | F9: =+D9*(1+$P$5) -> 3500 | G9: =+F9*12 -> 42000 | H9: =+F9*(1+$P$5) -> 3500 | I9: =+H9*12 -> 42000 | J9: =+H9*(1+$P$5) -> 3500 | K9: =+J9*12 -> 42000 | L9: =+E9+G9+I9+K9+C9 -> 210000
A10: Esp. Planificacion y Monitorieo | B10: =+B9 -> 3500 | C10: =+B10*12 -> 42000 | D10: =+B10*(1+$P$5) -> 3500 | E10: =+D10*12 -> 42000 | F10: =+D10*(1+$P$5) -> 3500 | G10: =+F10*12 -> 42000 | H10: =+F10*(1+$P$5) -> 3500 | I10: =+H10*12 -> 42000 | J10: =+H10*(1+$P$5) -> 3500 | K10: =+J10*12 -> 42000 | L10: =+E10+G10+I10+K10+C10 -> 210000
A11: Esp. Ambiental y Social | B11: =+B10 -> 3500 | C11: =+B11*12 -> 42000 | D11: =+B11*(1+$P$5) -> 3500 | E11: =+D11*12 -> 42000 | F11: =+D11*(1+$P$5) -> 3500 | G11: =+F11*12 -> 42000 | H11: =+F11*(1+$P$5) -> 3500 | I11: =+H11*12 -> 42000 | J11: =+H11*(1+$P$5) -> 3500 | K11: =+J11*12 -> 42000 | L11: =+E11+G11+I11+K11+C11 -> 210000
A12: Esp. Técnico (Agua No Contabilizada) | B12: =+B11 -> 3500 | C12: =+B12*12 -> 42000 | D12: =+B12*(1+$P$5) -> 3500 | E12: =+D12*12 -> 42000 | F12: =+D12*(1+$P$5) -> 3500 | G12: =+F12*12 -> 42000 | H12: =+F12*(1+$P$5) -> 3500 | I12: =+H12*12 -> 42000 | J12: =+H12*(1+$P$5) -> 3500 | K12: =+J12*12 -> 42000 | L12: =+E12+G12+I12+K12+C12 -> 210000
A13: Esp. Técnico (Efic. Energética) | B13: =+B12 -> 3500 | C13: =+B13*12 -> 42000 | D13: =+B13*(1+$P$5) -> 3500 | E13: =+D13*12 -> 42000 | F13: =+D13*(1+$P$5) -> 3500 | G13: =+F13*12 -> 42000 | H13: =+F13*(1+$P$5) -> 3500 | I13: =+H13*12 -> 42000 | J13: =+H13*(1+$P$5) -> 3500 | K13: =+J13*12 -> 42000 | L13: =+E13+G13+I13+K13+C13 -> 210000
A14: 3 Profesionales de apoyo: AdmIn, Adquisiciones, Técnico | B14: =1100*3 -> 3300 | C14: =+B14*12 -> 39600 | D14: =+B14*(1+$P$5) -> 3300 | E14: =+D14*12 -> 39600 | F14: =+D14*(1+$P$5) -> 3300 | G14: =+F14*12 -> 39600 | H14: =+F14*(1+$P$5) -> 3300 | I14: =+H14*12 -> 39600 | J14: =+H14*(1+$P$5) -> 3300 | K14: =+J14*12 -> 39600 | L14: =+E14+G14+I14+K14+C14 -> 198000
A15: Subtotal Recursos Humanos personal UE | B15: =SUM(B6:B14) -> 32800 | C15: =SUM(C6:C14) -> 393600 | D15: =SUM(D6:D14) -> 32800 | E15: =SUM(E6:E14) -> 393600 | F15: =SUM(F6:F14) -> 32800 | G15: =SUM(G6:G14) -> 393600 | H15: =SUM(H6:H14) -> 32800 | I15: =SUM(I6:I14) -> 393600 | ... L15: =SUM(L6:L14) -> 1968000
A16: Arrendamiento local | B16: 4000 | C16: =+B16*12 -> 48000 | D16: =+B16*(1+$P$5) -> 4000 | E16: =+D16*12 -> 48000 | F16: =+D16*(1+$P$5) -> 4000 | G16: =+F16*12 -> 48000 | H16: =+F16*(1+$P$5) -> 4000 | I16: =+H16*12 -> 48000 | J16: =+H16*(1+$P$5) -> 4000 | K16: =+J16*12 -> 48000 | L16: =+E16+G16+I16+K16+C16 -> 240000
A17: Comunicacion Social - Logistica | B17: 2000 | C17: =+B17*12 -> 24000 | D17: =+B17*(1+$P$5) -> 2000 | E17: =+D17*12 -> 24000 | F17: =+D17*(1+$P$5) -> 2000 | G17: =+F17*12 -> 24000 | H17: =+F17*(1+$P$5) -> 2000 | I17: =+H17*12 -> 24000 | J17: =+H17*(1+$P$5) -> 2000 | K17: =+J17*12 -> 24000 | L17: =+E17+G17+I17+K17+C17 -> 120000
A18: Seguridad y salud en el trabajo (EPP) | B18: =4*271 -> 1084 | C18: =+B18*12 -> 13008 | D18: =+B18*(1+$P$5) -> 1084 | E18: =+D18*12 -> 13008 | F18: =+D18*(1+$P$5) -> 1084 | G18: =+F18*12 -> 13008 | H18: =+F18*(1+$P$5) -> 1084 | I18: =+H18*12 -> 13008 | J18: =+H18*(1+$P$5) -> 1084 | K18: =+J18*12 -> 13008 | L18: =+E18+G18+I18+K18+C18 -> 65040
A19: Agua, luz | B19: 500 | C19: =+B19*12 -> 6000 | D19: =+B19*(1+$P$5) -> 500 | E19: =+D19*12 -> 6000 | F19: =+D19*(1+$P$5) -> 500 | G19: =+F19*12 -> 6000 | H19: =+F19*(1+$P$5) -> 500 | I19: =+H19*12 -> 6000 | J19: =+H19*(1+$P$5) -> 500 | K19: =+J19*12 -> 6000 | L19: =+E19+G19+I19+K19+C19 -> 30000
A20: Vigilancia (2 guardas, turnos de 24 horas) | B20: =600*2 -> 1200 | C20: =+(B20*12)+2000 -> 16400 | D20: =+B20*(1+$P$5) -> 1200 | E20: =+D20*12 -> 14400 | F20: =+D20*(1+$P$5) -> 1200 | G20: =+F20*12 -> 14400 | H20: =+F20*(1+$P$5) -> 1200 | I20: =+H20*12 -> 14400 | J20: =+H20*(1+$P$5) -> 1200 | K20: =+J20*12 -> 14400 | L20: =+E20+G20+I20+K20+C20 -> 74000
A21: Aseo y Cafeteria | B21: 1000 | C21: =+(B21*12)+3000 -> 15000 | D21: =+B21*(1+$P$5) -> 1000 | E21: =+D21*12 -> 12000 | F21: =+D21*(1+$P$5) -> 1000 | G21: =+F21*12 -> 12000 | H21: =+F21*(1+$P$5) -> 1000 | I21: =+H21*12 -> 12000 | J21: =+H21*(1+$P$5) -> 1000 | K21: =+J21*12 -> 12000 | L21: =+E21+G21+I21+K21+C21 -> 63000
A22: Papeleria | B22: 1200 | C22: =+B22*12 -> 14400 | D22: =+B22*(1+$P$5) -> 1200 | E22: =+D22*12 -> 14400 | F22: =+D22*(1+$P$5) -> 1200 | G22: =+F22*12 -> 14400 | H22: =+F22*(1+$P$5) -> 1200 | I22: =+H22*12 -> 14400 | J22: =+H22*(1+$P$5) -> 1200 | K22: =+J22*12 -> 14400 | L22: =+E22+G22+I22+K22+C22 -> 72000
A23: Vehiculo (3) | B23: =30000*3 -> 90000 | C23: =+B23*1 -> 90000 | D23: 0 | E23: =+D23*12 -> 0 | F23: =+D23*(1+$P$5) -> 0 | G23: =+F23*12 -> 0 | H23: =+F23*(1+$P$5) -> 0 | I23: =+H23*12 -> 0 | J23: =+H23*(1+$P$5) -> 0 | K23: =+J23*12 -> 0 | L23: =+E23+G23+I23+K23+C23 -> 90000
A24: Computadores (11) | B24: =1200*11 -> 13200 | C24: =+B24*12 -> 158400 | D24: 0 | E24: =+D24*12 -> 0 | F24: =+D24*(1+$P$5) -> 0 | G24: =+F24*12 -> 0 | H24: =+F24*(1+$P$5) -> 0 | I24: =+H24*12 -> 0 | J24: =+H24*(1+$P$5) -> 0 | K24: =+J24*12 -> 0 | L24: =+E24+G24+I24+K24+C24 -> 158400
A25: Fotocopiadora | B25: 5000 | C25: =+B25*1 -> 5000 | D25: 0 | E25: =+D25*12 -> 0 | F25: =+D25*(1+$P$5) -> 0 | G25: =+F25*12 -> 0 | H25: =+F25*(1+$P$5) -> 0 | I25: =+H25*12 -> 0 | J25: =+H25*(1+$P$5) -> 0 | K25: =+J25*12 -> 0 | L25: =+E25+G25+I25+K25+C25 -> 5000
A26: Internet dedicado. | B26: 500 | C26: =+B26*12 -> 6000 | D26: =+B26*(1+$P$5) -> 500 | E26: =+D26*12 -> 6000 | F26: =+D26*(1+$P$5) -> 500 | G26: =+F26*12 -> 6000 | H26: =+F26*(1+$P$5) -> 500 | I26: =+H26*12 -> 6000 | J26: =+H26*(1+$P$5) -> 500 | K26: =+J26*12 -> 6000 | L26: =+E26+G26+I26+K26+C26 -> 30000
A27: Software | B27: 450 | C27: =+(B27*11)+25000 -> 29950 | D27: =+B27*(1+$P$5) -> 450 | E27: =+D27*12 -> 5400 | F27: =+D27*(1+$P$5) -> 450 | G27: =+F27*12 -> 5400 | H27: =+F27*(1+$P$5) -> 450 | I27: =+H27*12 -> 5400 | J27: =+H27*(1+$P$5) -> 450 | K27: =+J27*12 -> 5400 | L27: =+E27+G27+I27+K27+C27 -> 51550
A28: Subtotal Gastos de Operación y Logística UE | B28: =SUM(B16:B27) -> 120134 | C28: =SUM(C16:C27) -> 426158 | D28: =SUM(D16:D27) -> 11934 | E28: =SUM(E16:E27) -> 143208 | F28: =SUM(F16:F27) -> 11934 | G28: =SUM(G16:G27) -> 143208 | H28: =SUM(H16:H27) -> 11934 | I28: =SUM(I16:I27) -> 143208 | ... K28: =SUM(K16:K27) -> 143208 | L28: =+E28+G28+I28+K28+C28 -> 998990
A29: Evaluacion intermedia y final | F29: 0 | G29: 100000 | K29: 150000 | L29: =+E29+G29+I29+K29+C29 -> 250000
A30: Auditoria financiera programa | C30: 50000 | E30: =+C30 -> 50000 | G30: =+E30 -> 50000 | I30: =+G30 -> 50000 | K30: =+I30 -> 50000 | L30: =+E30+G30+I30+K30+C30 -> 250000
A31: TOTAL | C31: =+C15+C28+C29+C30 -> 869758 | E31: =+E15+E28+E29+E30 -> 586808 | G31: =+G15+G28+G29+G30 -> 686808 | I31: =+I15+I28+I29+I30 -> 586808 | K31: =+K15+K28+K29+K30 -> 736808 | L31: =+E31+G31+I31+K31+C31 -> 3466990
A33: Costos Administración, M&E Y Auditoria | B33: Cantidad | C33: Costos Unitario | D33: Total
A34: Administración | B34: 1 | C34: 3000000 | D34: =+C34*B34 -> 3000000
A35: Auditoria | B35: 5 | C35: 50000 | D35: =+C35*B35 -> 250000
A36: Evaluación Intermedia | B36: 1 | C36: 100000 | D36: =+C36*B36 -> 100000
A37: Evaluación Final | B37: 1 | C37: 150000 | D37: =+C37*B37 -> 150000
A38: TOTAL | D38: =SUM(D34:D37) -> 3500000

Sheet Costos desglosados_C1 y C2
A1: PRESTAMO BID - ANDA - V0 | F1: 44699
D3: 150 MM USD | N3: 100 MM USD | O3: DIFERENCIA | P3: Ref. Cuadro de Costos
A5: Descripción | B5: Unidad | C5: Cantidad | D5: PU (USD) | E5: P Total (USD) | G5: Import. | H5: Local | I5: M.O. | J5: ING./SUP. | L5: Componente | M5: Muestra
A6: REFUERZO DE LA PRODUCCIÓN DEL SISTEMA NORTE | F6: =SUM(E7:E9) -> 4665083.6 | G6: =+SUMPRODUCT($E7:$E9,G7:G9) -> 1963987.6 | H6: =+SUMPRODUCT($E7:$E9,H7:H9) -> 744862.55 | I6: =+SUMPRODUCT($E7:$E9,I7:I9) -> 1529725.1 | J6: =+SUMPRODUCT($E7:$E9,J7:J9) -> 426508.36 | L6: 2 | M6: x | N6: =+F6 -> 4665083.6 | O6: =+N6-F6 -> 0 | P6: 2.1
A7: 6 nuevos pozos en recintos 3ª, 4 y 7 de Opico, Jabalí 1 y 2, Colombia 4 | B7: U | C7: 6 | D7: 417000 | E7: =+C7*D7 -> 2502000 | G7: 0.3 | H7: 0.2 | I7: 0.4 | J7: 0.1
A8: Fondo para rehabilitación de los pozos existentes (equipos de bombeo, instrumentación, instalaciones eléctricas e hidromecánicas) | B8: U | C8: 1 | D8: 800000 | E8: =+C8*D8 -> 800000 | G8: 0.75 | H8: 0.05 | I8: 0.15 | J8: 0.05
A9: Alimentacion eléctrica de nuevos pozos | E9: =SUM(E10:E11) -> 1363083.6 | G9: 0.45 | H9: 0.15 | I9: 0.3 | J9: 0.1
A10: Pozos de Opico | E10: 701087 | G10: 0.45 | H10: 0.15 | I10: 0.3 | J10: 0.1
A11: Pozos en Zona Colombia y Jabalí | E11: 661996.63 | G11: 0.45 | H11: 0.15 | I11: 0.3 | J11: 0.1
A12: GESTIÓN DE LOS RECURSOS HÍDRICOS | F12: =SUM(E13:E16) -> 1000000 | G12: =+G13*$E13+G14*$E14+G15*$E15+G16*$E16 -> 380000 | H12: =+H13*$E13+H14*$E14+H15*$E15+H16*$E16 -> 140000 | I12: =+I13*$E13+I14*$E14+I15*$E15+I16*$E16 -> 220000 | J12: =+J13*$E13+J14*$E14+J15*$E15+J16*$E16 -> 260000 | L12: 2 | M12: No | N12: =+N13+N14+N15+N16 -> 800000 | O12: =+N12-F12 -> -200000 | P12: 2.7 | R12: =SUM(R6:R11) -> 0 | S12: =SUM(S6:S11) -> 0
A13: Pozo de exploración Opico | B13: Total | C13: 1 | D13: 200000 | E13: =+C13*D13 -> 200000 | G13: 0.3 | H13: 0.2 | I13: 0.4 | J13: 0.1 | N13: =+E13 -> 200000
A14: Censo de pozos y mapa piezométrico del acuífero | B14: Total | C14: 1 | D14: 100000 | E14: =+C14*D14 -> 100000 | I14: 0.9 | J14: 0.1 | N14: =+E14 -> 100000
A15: Red de monitoreo con seguimiento estacional | B15: Total | C15: 1 | D15: 500000 | E15: =+C15*D15 -> 500000 | G15: 0.6 | H15: 0.2 | I15: 0.1 | J15: 0.1 | N15: 400000 | O15: =+N15-E15 -> -100000
A16: Modelización del acuífero con fines predictivos | B16: Total | C16: 1 | D16: 100000 | E16: 200000 | G16: 0.1 | J16: 0.9 | N16: 100000 | O16: =+N16-E16 -> -100000
A17: REFUERZO DE LAS CONDUCCIONES ENTRE POZOS Y LA ESTACIÓN DE BOMBEO LA TOMA | F17: =+E18+E37 -> 6148000 | G17: =+G18+G37 -> 1790460 | H17: =+H18+H37 -> 2183100 | I17: =+I18+I37 -> 1559640 | J17: =+J18+J37 -> 614800 | L17: 2 | M17: x | N17: =+F17 -> 6148000 | O17: =+N17-F17 -> 0 | P17: 2.2
A18: Zona Opico: | E18: =+E19+E27+E35+E29 -> 5513000 | G18: =+G19+G27+G29+G35 -> 1517460 | H18: =+H19+H27+H29+H35 -> 2027800 | I18: =+I19+I27+I29+I35 -> 1416440 | J18: =+J19+J27+J29+J35 -> 551300
A19: Tuberias | E19: =SUM(E20:E22) -> 2890000 | G19: =+$E19*G20 -> 1156000 | H19: =+$E19*H20 -> 780300 | I19: =+$E19*I20 -> 664700 | J19: =+$E19*J20 -> 289000
A20: Duplicación tuberia Tanque Opico - EB San Lorenzo - 24" - 2.5 km | B20: m | C20: 2500 | D20: 800 | E20: =+C20*D20 -> 2000000 | G20: 0.4 | H20: 0.27 | I20: 0.23 | J20: 0.1
A21: Sustitución válvulas de aire de la conducción existente 24" | B21: U | C21: 4 | D21: 30000 | E21: =+C21*D21 -> 120000
A22: Tuberías de refuerzo entre pozos y tanque Opico | B22: m | E22: =+SUMPRODUCT(C23:C26,D23:D26) -> 770000
A23: - 400m DN 24" | B23: m | C23: 400 | D23: 800
A24: - 500m DN 16" | B24: m | C24: 500 | D24: 500
A25: - 600m DN 10" | B25: m | C25: 600 | D25: 300
A26: - 100m DN 8" | B26: m | C26: 100 | D26: 200
A27: Nuevo tanque Opico - 4000 m3 | B27: Total | C27: 1 | D27: =1652500*1.2+200000 -> 2183000 | E27: =+C27*D27 -> 2183000 | G27: =+$E27*G28 -> 261960 | H27: =+$E27*H28 -> 1091500 | I27: =+$E27*I28 -> 611240 | J27: =+$E27*J28 -> 218300
G28: 0.12 | H28: 0.5 | I28: 0.28 | J28: 0.1
A29: Equipos de monitoreo operacional | B29: U | E29: =+SUMPRODUCT(C30:C34,D30:D34) -> 90000 | G29: =+$E29*G30 -> 54000 | H29: =+$E29*H30 -> 9000 | I29: =+$E29*I30 -> 18000 | J29: =+$E29*J30 -> 9000
A30: - Macromedidor con data loggers (cada pozo) | B30: U | C30: 10 | D30: 5000 | G30: 0.6 | H30: 0.1 | I30: 0.2 | J30: 0.1
A31: - Macromedidor con data logger salida tanque Opico actual 24" | B31: U | C31: 1 | D31: 10000
A32: - Macromedidor con data logger salida tanque Opico actual 24" | B32: U | C32: 1 | D32: 10000
A33: - Mediciones niveles con data logger de tanques Opico y Opico nuevo | B33: U | C33: 2 | D33: 2500
A34: - Macromedidor DN 36" salida de San Lorenzo (control de continuidad de caudal) | B34: U | C34: 1 | D34: 15000
A35: Sustitución valvulerias, empalme nueva conducción y puesta fuera de servicio Estación San Lorenzo | B35: Total | C35: 1 | D35: 350000 | E35: =+C35*D35 -> 350000 | G35: =+$E35*G36 -> 45500 | H35: =+$E35*H36 -> 147000 | I35: =+$E35*I36 -> 122500 | J35: =+$E35*J36 -> 35000
G36: 0.13 | H36: 0.42 | I36: 0.35 | J36: 0.1
A37: Zona Colombia: | E37: =SUM(E38:E45) -> 635000 | G37: =+G38+G41 -> 273000 | H37: =+H38+H41 -> 155300 | I37: =+I38+I41 -> 143200 | J37: =+J38+J41 -> 63500
A38: Tuberías de refuerzo entre pozos y tanque Colombia | B38: m | E38: =+C39*D39+C40*D40 -> 540000 | G38: =+$E38*G39 -> 216000 | H38: =+$E38*H39 -> 145800 | I38: =+$E38*I39 -> 124200 | J38: =+$E38*J39 -> 54000
A39: - 500m DN 20" | B39: m | C39: 400 | D39: 600 | G39: 0.4 | H39: 0.27 | I39: 0.23 | J39: 0.1
A40: - 1000m DN 10" | B40: m | C40: 1000 | D40: 300
A41: Equipos de monitoreo operacional | B41: Total | E41: =+SUMPRODUCT(C42:C45,D42:D45) -> 95000 | G41: =+$E41*G42 -> 57000 | H41: =+$E41*H42 -> 9500 | I41: =+$E41*I42 -> 19000 | J41: =+$E41*J42 -> 9500
A42: - Macromedidor con data loggers (cada pozo) | B42: U | C42: 10 | D42: 7000 | G42: 0.6 | H42: 0.1 | I42: 0.2 | J42: 0.1
...

Sheet Costos Desglosados C3
B2: Componente 3 - Mejora de la Gestión | C2: Unidad | D2: Cantidad | E2: Costo Unitario (USD) | F2: Total (USD)
B4: Componente 3 - Mejora de la Gestión | E4: =SUM(E5:E17) -> 11600000 | F4: =+F5+F6+F7+F8+F13+F14+F15+F16+F17 -> 11600000
A5: 1 | B5: Plan de desarrollo organizacional de ANDA diseñado e implementado | C5: Suma alzada | D5: 1 | E5: 1475000 | F5: =+E5*D5 -> 1475000
A6: 2 | B6: Plan de accion de Gobierno Coporativo implementado ( al menos 3 actividades) | C6: Suma alzada | D6: 1 | E6: 200000 | F6: =+E6*D6 -> 200000
A7: 3 | B7: Plan de modernizacion tecnologica de ANDA diseñado e implementado (diseño + RP) | C7: Suma alzada | D7: 1 | E7: 4500000 | F7: =+E7*D7 -> 4500000
A8: 4 | B8: Actividades de Genero | F8: =SUM(F9:F12) -> 75000
A9: 4.1 | B9: Adquisición de equipos para la Unidad de Genero | C9: Suma alzada | D9: 1 | E9: 20000 | F9: =+E9*D9 -> 20000
A10: 4.2 | B10: Política y diagnóstico de género actualizado | C10: Suma alzada | D10: 1 | E10: 20000 | F10: =+E10*D10 -> 20000
A11: 4.3 | B11: Módulo de indicadores de género en el sistema de información desarrollado | C11: Suma alzada | D11: 1 | E11: 15000 | F11: =+E11*D11 -> 15000
A12: 4.4 | B12: Estrategia institucional de inclusión laboral de personas con discapacidad entre los trabajadores de ANDA diseñada | C12: Suma alzada | D12: 1 | E12: 20000 | F12: =+E12*D12 -> 20000
A13: 5 | B13: Plan Maestro Agua y Saneamiento para el Area Metropolitana de San Salvador desarrollado (aprobado por Junta) (en ejecución) | C13: Suma alzada | D13: 1 | E13: 2000000 | F13: =+E13*D13 -> 2000000
A14: 6 | B14: Programa de Planificiación financiera y estrategica implementado | C14: Suma alzada | D14: 1 | E14: 1700000 | F14: =+E14*D14 -> 1700000
A15: 7 | B15: Plan de comunicacion diseñado e implementado | C15: Suma alzada | D15: 1 | E15: 300000 | F15: =+E15*D15 -> 300000
A16: 8 | B16: Normas tecnicas de ANDA actualizadas | C16: Suma alzada | D16: 1 | E16: 350000 | F16: =+E16*D16 -> 350000
A17: 9 | B17: Laboratorio de calidad de agua equipado | C17: Suma alzada | D17: 1 | E17: 1000000 | F17: =+E17*D17 -> 1000000
